--lifted mostly straight from ethereal

local _ = {name = "air", prob = 0}
local M = {name = "default:coral_orange", prob = 255}
local T = {name = "default:coral_skeleton", prob = 255}
--local P = {name = "realms:mushroom_pore", prob = 255}

bd_odd_biomes.mushroom_giant_tall = {

	size = {x = 18, y = 17, z = 18},

	yslice_prob = {
		{ypos = 2, prob = 200},
		{ypos = 9, prob = 200},
		{ypos =10, prob = 200},
	},

	data = {
--1
	_,_,_,_,_,_,_,_,_,_,_,_,_,_,_,_,_,_,
	_,_,_,_,_,_,_,_,_,_,_,_,_,_,_,_,_,_,
	_,_,_,_,_,_,_,_,_,_,_,_,_,_,_,_,_,_,
	_,_,_,_,_,_,_,_,_,_,_,_,_,_,_,_,_,_,
	_,_,_,_,_,_,_,_,_,_,_,_,_,_,_,_,_,_,
	_,_,_,_,_,_,_,_,_,_,_,_,_,_,_,_,_,_,
	_,_,_,_,_,_,_,_,_,_,_,_,_,_,_,_,_,_,
	_,_,_,_,_,_,_,_,_,_,_,_,_,_,_,_,_,_,
	_,_,_,_,_,_,_,_,_,_,_,_,_,_,_,_,_,_,
	_,_,_,_,_,_,_,_,_,_,_,_,_,_,_,_,_,_,
	_,_,_,_,_,_,_,_,_,_,_,_,_,_,_,_,_,_,
	_,_,_,_,_,_,_,_,_,_,_,_,_,_,_,_,_,_,
	_,_,_,_,_,_,_,_,_,_,_,_,_,_,_,_,_,_,
	_,_,_,_,_,_,_,_,_,_,_,_,_,_,_,_,_,_,
	_,_,_,_,_,_,M,M,M,M,M,M,_,_,_,_,_,_,
	_,_,_,_,_,_,_,_,_,_,_,_,_,_,_,_,_,_,
	_,_,_,_,_,_,_,_,_,_,_,_,_,_,_,_,_,_,
--1 2 3 4 5 6 7 8 9 9 8 7 6 5 4 3 2 1

--2
	_,_,_,_,_,_,_,_,_,_,_,_,_,_,_,_,_,_,
	_,_,_,_,_,_,_,_,_,_,_,_,_,_,_,_,_,_,
	_,_,_,_,_,_,_,_,_,_,_,_,_,_,_,_,_,_,
	_,_,_,_,_,_,_,_,_,_,_,_,_,_,_,_,_,_,
	_,_,_,_,_,_,_,_,_,_,_,_,_,_,_,_,_,_,
	_,_,_,_,_,_,_,_,_,_,_,_,_,_,_,_,_,_,
	_,_,_,_,_,_,_,_,_,_,_,_,_,_,_,_,_,_,
	_,_,_,_,_,_,_,_,_,_,_,_,_,_,_,_,_,_,
	_,_,_,_,_,_,_,_,_,_,_,_,_,_,_,_,_,_,
	_,_,_,_,_,_,_,_,_,_,_,_,_,_,_,_,_,_,
	_,_,_,_,_,_,_,_,_,_,_,_,_,_,_,_,_,_,
	_,_,_,_,_,_,_,_,_,_,_,_,_,_,_,_,_,_,
	_,_,_,_,_,_,_,_,_,_,_,_,_,_,_,_,_,_,
	_,_,_,_,_,_,_,_,_,_,_,_,_,_,_,_,_,_,
	_,_,_,_,_,M,M,M,M,M,M,M,M,_,_,_,_,_,
	_,_,_,_,_,_,_,_,_,_,_,_,_,_,_,_,_,_,
	_,_,_,_,_,_,_,_,_,_,_,_,_,_,_,_,_,_,
--1 2 3 4 5 6 7 8 9 9 8 7 6 5 4 3 2 1

--3
	_,_,_,_,_,_,_,_,_,_,_,_,_,_,_,_,_,_,
	_,_,_,_,_,_,_,_,_,_,_,_,_,_,_,_,_,_,
	_,_,_,_,_,_,_,_,_,_,_,_,_,_,_,_,_,_,
	_,_,_,_,_,_,_,_,_,_,_,_,_,_,_,_,_,_,
	_,_,_,_,_,_,_,_,_,_,_,_,_,_,_,_,_,_,
	_,_,_,_,_,_,_,_,_,_,_,_,_,_,_,_,_,_,
	_,_,_,_,_,_,_,_,_,_,_,_,_,_,_,_,_,_,
	_,_,_,_,_,_,_,_,_,_,_,_,_,_,_,_,_,_,
	_,_,_,_,_,_,_,_,_,_,_,_,_,_,_,_,_,_,
	_,_,_,_,_,_,_,_,_,_,_,_,_,_,_,_,_,_,
	_,_,_,_,_,_,_,_,_,_,_,_,_,_,_,_,_,_,
	_,_,_,_,_,_,_,_,_,_,_,_,_,_,_,_,_,_,
	_,_,_,_,_,_,_,_,_,_,_,_,_,_,_,_,_,_,
	_,_,_,_,_,_,_,_,_,_,_,_,_,_,_,_,_,_,
	_,_,_,_,M,M,M,M,M,M,M,M,M,M,_,_,_,_,
	_,_,_,_,_,_,_,_,_,_,_,_,_,_,_,_,_,_,
	_,_,_,_,_,_,_,_,_,_,_,_,_,_,_,_,_,_,
--1 2 3 4 5 6 7 8 9 9 8 7 6 5 4 3 2 1

--4
	_,_,_,_,_,_,_,_,_,_,_,_,_,_,_,_,_,_,
	_,_,_,_,_,_,_,_,_,_,_,_,_,_,_,_,_,_,
	_,_,_,_,_,_,_,_,_,_,_,_,_,_,_,_,_,_,
	_,_,_,_,_,_,_,_,_,_,_,_,_,_,_,_,_,_,
	_,_,_,_,_,_,_,_,_,_,_,_,_,_,_,_,_,_,
	_,_,_,_,_,_,_,_,_,_,_,_,_,_,_,_,_,_,
	_,_,_,_,_,_,_,_,_,_,_,_,_,_,_,_,_,_,
	_,_,_,_,_,_,_,_,_,_,_,_,_,_,_,_,_,_,
	_,_,_,_,_,_,_,_,_,_,_,_,_,_,_,_,_,_,
	_,_,_,_,_,_,_,_,_,_,_,_,_,_,_,_,_,_,
	_,_,_,_,_,_,_,_,_,_,_,_,_,_,_,_,_,_,
	_,_,_,_,_,_,_,_,_,_,_,_,_,_,_,_,_,_,
	_,_,_,_,_,_,_,_,_,_,_,_,_,_,_,_,_,_,
	_,_,_,_,_,_,_,_,_,_,_,_,_,_,_,_,_,_,
	_,_,_,M,M,M,M,_,_,_,_,M,M,M,M,_,_,_,
	_,_,_,_,_,_,_,M,M,M,M,_,_,_,_,_,_,_,
	_,_,_,_,_,_,_,_,_,_,_,_,_,_,_,_,_,_,
--1 2 3 4 5 6 7 8 9 9 8 7 6 5 4 3 2 1

--5
	_,_,_,_,_,_,_,_,_,_,_,_,_,_,_,_,_,_,
	_,_,_,_,_,_,_,_,_,_,_,_,_,_,_,_,_,_,
	_,_,_,_,_,_,_,_,_,_,_,_,_,_,_,_,_,_,
	_,_,_,_,_,_,_,_,_,_,_,_,_,_,_,_,_,_,
	_,_,_,_,_,_,_,_,_,_,_,_,_,_,_,_,_,_,
	_,_,_,_,_,_,_,_,_,_,_,_,_,_,_,_,_,_,
	_,_,_,_,_,_,_,_,_,_,_,_,_,_,_,_,_,_,
	_,_,_,_,_,_,_,_,_,_,_,_,_,_,_,_,_,_,
	_,_,_,_,_,_,_,_,_,_,_,_,_,_,_,_,_,_,
	_,_,_,_,_,_,_,_,_,_,_,_,_,_,_,_,_,_,
	_,_,_,_,_,_,_,_,_,_,_,_,_,_,_,_,_,_,
	_,_,_,_,_,_,_,_,_,_,_,_,_,_,_,_,_,_,
	_,_,_,_,_,_,_,_,_,_,_,_,_,_,_,_,_,_,
	_,_,_,_,_,_,_,_,_,_,_,_,_,_,_,_,_,_,
	_,M,M,M,M,_,_,_,_,_,_,_,_,M,M,M,M,_,
	_,_,_,_,_,M,M,M,M,M,M,M,M,_,_,_,_,_,
	_,_,_,_,_,_,_,_,_,_,_,_,_,_,_,_,_,_,
--1 2 3 4 5 6 7 8 9 9 8 7 6 5 4 3 2 1

--6
	_,_,_,_,_,_,_,_,_,_,_,_,_,_,_,_,_,_,
	_,_,_,_,_,_,_,_,_,_,_,_,_,_,_,_,_,_,
	_,_,_,_,_,_,_,_,_,_,_,_,_,_,_,_,_,_,
	_,_,_,_,_,_,_,_,_,_,_,_,_,_,_,_,_,_,
	_,_,_,_,_,_,_,_,_,_,_,_,_,_,_,_,_,_,
	_,_,_,_,_,_,_,_,_,_,_,_,_,_,_,_,_,_,
	_,_,_,_,_,_,_,_,_,_,_,_,_,_,_,_,_,_,
	_,_,_,_,_,_,_,_,_,_,_,_,_,_,_,_,_,_,
	_,_,_,_,_,_,_,_,_,_,_,_,_,_,_,_,_,_,
	_,_,_,_,_,_,_,_,_,_,_,_,_,_,_,_,_,_,
	_,_,_,_,_,_,_,_,_,_,_,_,_,_,_,_,_,_,
	_,_,_,_,_,_,_,_,_,_,_,_,_,_,_,_,_,_,
	_,_,_,_,_,_,_,_,_,_,_,_,_,_,_,_,_,_,
	_,_,_,_,_,_,_,_,_,_,_,_,_,_,_,_,_,_,
	_,M,M,M,_,_,_,_,_,_,_,_,_,_,M,M,M,_,
	_,_,_,_,M,M,M,M,M,M,M,M,M,M,_,_,_,_,
	_,_,_,_,_,_,_,_,_,_,_,_,_,_,_,_,_,_,
--1 2 3 4 5 6 7 8 9 9 8 7 6 5 4 3 2 1

--7
	_,_,_,_,_,_,_,_,_,_,_,_,_,_,_,_,_,_,
	_,_,_,_,_,_,_,_,_,_,_,_,_,_,_,_,_,_,
	_,_,_,_,_,_,_,_,_,_,_,_,_,_,_,_,_,_,
	_,_,_,_,_,_,_,_,_,_,_,_,_,_,_,_,_,_,
	_,_,_,_,_,_,_,_,_,_,_,_,_,_,_,_,_,_,
	_,_,_,_,_,_,_,_,_,_,_,_,_,_,_,_,_,_,
	_,_,_,_,_,_,_,_,_,_,_,_,_,_,_,_,_,_,
	_,_,_,_,_,_,_,_,_,_,_,_,_,_,_,_,_,_,
	_,_,_,_,_,_,_,_,_,_,_,_,_,_,_,_,_,_,
	_,_,_,_,_,_,_,_,_,_,_,_,_,_,_,_,_,_,
	_,_,_,_,_,_,_,_,_,_,_,_,_,_,_,_,_,_,
	_,_,_,_,_,_,_,_,_,_,_,_,_,_,_,_,_,_,
	_,_,_,_,_,_,_,_,_,_,_,_,_,_,_,_,_,_,
	_,_,_,_,_,_,_,_,_,_,_,_,_,_,_,_,_,_,
	M,M,M,M,_,_,_,_,_,_,_,_,_,_,M,M,M,M,
	_,_,_,_,M,M,M,_,_,_,_,M,M,M,_,_,_,_,
	_,_,_,_,_,_,_,M,M,M,M,_,_,_,_,_,_,_,
--1 2 3 4 5 6 7 8 9 9 8 7 6 5 4 3 2 1

--8
	_,_,_,_,_,_,_,_,_,_,_,_,_,_,_,_,_,_,
	_,_,_,_,_,_,_,_,_,_,_,_,_,_,_,_,_,_,
	_,_,_,_,_,_,_,_,_,_,_,_,_,_,_,_,_,_,
	_,_,_,_,_,_,_,_,_,_,_,_,_,_,_,_,_,_,
	_,_,_,_,_,_,_,_,_,_,_,_,_,_,_,_,_,_,
	_,_,_,_,_,_,_,_,_,_,_,_,_,_,_,_,_,_,
	_,_,_,_,_,_,_,_,_,_,_,_,_,_,_,_,_,_,
	_,_,_,_,_,_,_,_,_,_,_,_,_,_,_,_,_,_,
	_,_,_,_,_,_,_,_,_,_,_,_,_,_,_,_,_,_,
	_,_,_,_,_,_,_,_,_,_,_,_,_,_,_,_,_,_,
	_,_,_,_,_,_,_,_,_,_,_,_,_,_,_,_,_,_,
	_,_,_,_,_,_,_,_,_,_,_,_,_,_,_,_,_,_,
	_,_,_,_,_,_,_,_,_,_,_,_,_,_,_,_,_,_,
	_,_,_,_,_,_,_,_,_,_,_,_,_,_,_,_,_,_,
	M,M,M,_,_,_,_,_,_,_,_,_,_,_,_,M,M,M,
	_,_,_,M,M,M,_,_,_,_,_,_,M,M,M,_,_,_,
	_,_,_,_,_,_,M,M,M,M,M,M,_,_,_,_,_,_,
--1 2 3 4 5 6 7 8 9 9 8 7 6 5 4 3 2 1

--9
	_,_,_,_,_,T,T,_,_,_,_,_,_,_,_,_,_,_,
	_,_,_,_,_,T,T,_,_,_,_,_,_,_,_,_,_,_,
	_,_,_,_,_,T,T,_,_,_,_,_,_,_,_,_,_,_,
	_,_,_,_,_,T,T,_,_,_,_,_,_,_,_,_,_,_,
	_,_,_,_,_,_,T,T,_,_,_,_,_,_,_,_,_,_,
	_,_,_,_,_,_,T,T,_,_,_,_,_,_,_,_,_,_,
	_,_,_,_,_,_,_,T,T,_,_,_,_,_,_,_,_,_,
	_,_,_,_,_,_,_,_,T,T,_,_,_,_,_,_,_,_,
	_,_,_,_,_,_,_,_,_,T,T,_,_,_,_,_,_,_,
	_,_,_,_,_,_,_,_,_,T,T,_,_,_,_,_,_,_,
	_,_,_,_,_,_,_,_,_,_,T,T,_,_,_,_,_,_,
	_,_,_,_,_,_,_,_,_,_,T,T,_,_,_,_,_,_,
	_,_,_,_,_,_,_,_,_,_,T,T,_,_,_,_,_,_,
	_,_,_,_,_,_,_,_,_,T,T,_,_,_,_,_,_,_,
	M,M,M,_,_,_,_,_,_,T,T,_,_,_,_,M,M,M,
	_,_,_,M,M,M,_,_,T,T,_,_,M,M,M,_,_,_,
	_,_,_,_,_,_,M,M,M,M,M,M,_,_,_,_,_,_,
--1 2 3 4 5 6 7 8 9 9 8 7 6 5 4 3 2 1

--9
	_,_,_,_,_,T,T,_,_,_,_,_,_,_,_,_,_,_,
	_,_,_,_,_,T,T,_,_,_,_,_,_,_,_,_,_,_,
	_,_,_,_,_,T,T,_,_,_,_,_,_,_,_,_,_,_,
	_,_,_,_,_,T,T,_,_,_,_,_,_,_,_,_,_,_,
	_,_,_,_,_,_,T,T,_,_,_,_,_,_,_,_,_,_,
	_,_,_,_,_,_,T,T,_,_,_,_,_,_,_,_,_,_,
	_,_,_,_,_,_,_,T,T,_,_,_,_,_,_,_,_,_,
	_,_,_,_,_,_,_,_,T,T,_,_,_,_,_,_,_,_,
	_,_,_,_,_,_,_,_,_,T,T,_,_,_,_,_,_,_,
	_,_,_,_,_,_,_,_,_,T,T,_,_,_,_,_,_,_,
	_,_,_,_,_,_,_,_,_,_,T,T,_,_,_,_,_,_,
	_,_,_,_,_,_,_,_,_,_,T,T,_,_,_,_,_,_,
	_,_,_,_,_,_,_,_,_,_,T,T,_,_,_,_,_,_,
	_,_,_,_,_,_,_,_,_,T,T,_,_,_,_,_,_,_,
	M,M,M,_,_,_,_,_,_,T,T,_,_,_,_,M,M,M,
	_,_,_,M,M,M,_,_,T,T,_,_,M,M,M,_,_,_,
	_,_,_,_,_,_,M,M,M,M,M,M,_,_,_,_,_,_,
--1 2 3 4 5 6 7 8 9 9 8 7 6 5 4 3 2 1

--8
	_,_,_,_,_,_,_,_,_,_,_,_,_,_,_,_,_,_,
	_,_,_,_,_,_,_,_,_,_,_,_,_,_,_,_,_,_,
	_,_,_,_,_,_,_,_,_,_,_,_,_,_,_,_,_,_,
	_,_,_,_,_,_,_,_,_,_,_,_,_,_,_,_,_,_,
	_,_,_,_,_,_,_,_,_,_,_,_,_,_,_,_,_,_,
	_,_,_,_,_,_,_,_,_,_,_,_,_,_,_,_,_,_,
	_,_,_,_,_,_,_,_,_,_,_,_,_,_,_,_,_,_,
	_,_,_,_,_,_,_,_,_,_,_,_,_,_,_,_,_,_,
	_,_,_,_,_,_,_,_,_,_,_,_,_,_,_,_,_,_,
	_,_,_,_,_,_,_,_,_,_,_,_,_,_,_,_,_,_,
	_,_,_,_,_,_,_,_,_,_,_,_,_,_,_,_,_,_,
	_,_,_,_,_,_,_,_,_,_,_,_,_,_,_,_,_,_,
	_,_,_,_,_,_,_,_,_,_,_,_,_,_,_,_,_,_,
	_,_,_,_,_,_,_,_,_,_,_,_,_,_,_,_,_,_,
	M,M,M,_,_,_,_,_,_,_,_,_,_,_,_,M,M,M,
	_,_,_,M,M,M,_,_,_,_,_,_,M,M,M,_,_,_,
	_,_,_,_,_,_,M,M,M,M,M,M,_,_,_,_,_,_,
--1 2 3 4 5 6 7 8 9 9 8 7 6 5 4 3 2 1

--7
	_,_,_,_,_,_,_,_,_,_,_,_,_,_,_,_,_,_,
	_,_,_,_,_,_,_,_,_,_,_,_,_,_,_,_,_,_,
	_,_,_,_,_,_,_,_,_,_,_,_,_,_,_,_,_,_,
	_,_,_,_,_,_,_,_,_,_,_,_,_,_,_,_,_,_,
	_,_,_,_,_,_,_,_,_,_,_,_,_,_,_,_,_,_,
	_,_,_,_,_,_,_,_,_,_,_,_,_,_,_,_,_,_,
	_,_,_,_,_,_,_,_,_,_,_,_,_,_,_,_,_,_,
	_,_,_,_,_,_,_,_,_,_,_,_,_,_,_,_,_,_,
	_,_,_,_,_,_,_,_,_,_,_,_,_,_,_,_,_,_,
	_,_,_,_,_,_,_,_,_,_,_,_,_,_,_,_,_,_,
	_,_,_,_,_,_,_,_,_,_,_,_,_,_,_,_,_,_,
	_,_,_,_,_,_,_,_,_,_,_,_,_,_,_,_,_,_,
	_,_,_,_,_,_,_,_,_,_,_,_,_,_,_,_,_,_,
	_,_,_,_,_,_,_,_,_,_,_,_,_,_,_,_,_,_,
	M,M,M,M,_,_,_,_,_,_,_,_,_,_,M,M,M,M,
	_,_,_,_,M,M,M,_,_,_,_,M,M,M,_,_,_,_,
	_,_,_,_,_,_,_,M,M,M,M,_,_,_,_,_,_,_,
--1 2 3 4 5 6 7 8 9 9 8 7 6 5 4 3 2 1

--6
	_,_,_,_,_,_,_,_,_,_,_,_,_,_,_,_,_,_,
	_,_,_,_,_,_,_,_,_,_,_,_,_,_,_,_,_,_,
	_,_,_,_,_,_,_,_,_,_,_,_,_,_,_,_,_,_,
	_,_,_,_,_,_,_,_,_,_,_,_,_,_,_,_,_,_,
	_,_,_,_,_,_,_,_,_,_,_,_,_,_,_,_,_,_,
	_,_,_,_,_,_,_,_,_,_,_,_,_,_,_,_,_,_,
	_,_,_,_,_,_,_,_,_,_,_,_,_,_,_,_,_,_,
	_,_,_,_,_,_,_,_,_,_,_,_,_,_,_,_,_,_,
	_,_,_,_,_,_,_,_,_,_,_,_,_,_,_,_,_,_,
	_,_,_,_,_,_,_,_,_,_,_,_,_,_,_,_,_,_,
	_,_,_,_,_,_,_,_,_,_,_,_,_,_,_,_,_,_,
	_,_,_,_,_,_,_,_,_,_,_,_,_,_,_,_,_,_,
	_,_,_,_,_,_,_,_,_,_,_,_,_,_,_,_,_,_,
	_,_,_,_,_,_,_,_,_,_,_,_,_,_,_,_,_,_,
	_,M,M,M,_,_,_,_,_,_,_,_,_,_,M,M,M,_,
	_,_,_,_,M,M,M,M,M,M,M,M,M,M,_,_,_,_,
	_,_,_,_,_,_,_,_,_,_,_,_,_,_,_,_,_,_,
--1 2 3 4 5 6 7 8 9 9 8 7 6 5 4 3 2 1

--5
	_,_,_,_,_,_,_,_,_,_,_,_,_,_,_,_,_,_,
	_,_,_,_,_,_,_,_,_,_,_,_,_,_,_,_,_,_,
	_,_,_,_,_,_,_,_,_,_,_,_,_,_,_,_,_,_,
	_,_,_,_,_,_,_,_,_,_,_,_,_,_,_,_,_,_,
	_,_,_,_,_,_,_,_,_,_,_,_,_,_,_,_,_,_,
	_,_,_,_,_,_,_,_,_,_,_,_,_,_,_,_,_,_,
	_,_,_,_,_,_,_,_,_,_,_,_,_,_,_,_,_,_,
	_,_,_,_,_,_,_,_,_,_,_,_,_,_,_,_,_,_,
	_,_,_,_,_,_,_,_,_,_,_,_,_,_,_,_,_,_,
	_,_,_,_,_,_,_,_,_,_,_,_,_,_,_,_,_,_,
	_,_,_,_,_,_,_,_,_,_,_,_,_,_,_,_,_,_,
	_,_,_,_,_,_,_,_,_,_,_,_,_,_,_,_,_,_,
	_,_,_,_,_,_,_,_,_,_,_,_,_,_,_,_,_,_,
	_,_,_,_,_,_,_,_,_,_,_,_,_,_,_,_,_,_,
	_,M,M,M,M,_,_,_,_,_,_,_,_,M,M,M,M,_,
	_,_,_,_,_,M,M,M,M,M,M,M,M,_,_,_,_,_,
	_,_,_,_,_,_,_,_,_,_,_,_,_,_,_,_,_,_,
--1 2 3 4 5 6 7 8 9 9 8 7 6 5 4 3 2 1


--4
	_,_,_,_,_,_,_,_,_,_,_,_,_,_,_,_,_,_,
	_,_,_,_,_,_,_,_,_,_,_,_,_,_,_,_,_,_,
	_,_,_,_,_,_,_,_,_,_,_,_,_,_,_,_,_,_,
	_,_,_,_,_,_,_,_,_,_,_,_,_,_,_,_,_,_,
	_,_,_,_,_,_,_,_,_,_,_,_,_,_,_,_,_,_,
	_,_,_,_,_,_,_,_,_,_,_,_,_,_,_,_,_,_,
	_,_,_,_,_,_,_,_,_,_,_,_,_,_,_,_,_,_,
	_,_,_,_,_,_,_,_,_,_,_,_,_,_,_,_,_,_,
	_,_,_,_,_,_,_,_,_,_,_,_,_,_,_,_,_,_,
	_,_,_,_,_,_,_,_,_,_,_,_,_,_,_,_,_,_,
	_,_,_,_,_,_,_,_,_,_,_,_,_,_,_,_,_,_,
	_,_,_,_,_,_,_,_,_,_,_,_,_,_,_,_,_,_,
	_,_,_,_,_,_,_,_,_,_,_,_,_,_,_,_,_,_,
	_,_,_,_,_,_,_,_,_,_,_,_,_,_,_,_,_,_,
	_,_,_,M,M,M,M,_,_,_,_,M,M,M,M,_,_,_,
	_,_,_,_,_,_,_,M,M,M,M,_,_,_,_,_,_,_,
	_,_,_,_,_,_,_,_,_,_,_,_,_,_,_,_,_,_,
--1 2 3 4 5 6 7 8 9 9 8 7 6 5 4 3 2 1

--3
	_,_,_,_,_,_,_,_,_,_,_,_,_,_,_,_,_,_,
	_,_,_,_,_,_,_,_,_,_,_,_,_,_,_,_,_,_,
	_,_,_,_,_,_,_,_,_,_,_,_,_,_,_,_,_,_,
	_,_,_,_,_,_,_,_,_,_,_,_,_,_,_,_,_,_,
	_,_,_,_,_,_,_,_,_,_,_,_,_,_,_,_,_,_,
	_,_,_,_,_,_,_,_,_,_,_,_,_,_,_,_,_,_,
	_,_,_,_,_,_,_,_,_,_,_,_,_,_,_,_,_,_,
	_,_,_,_,_,_,_,_,_,_,_,_,_,_,_,_,_,_,
	_,_,_,_,_,_,_,_,_,_,_,_,_,_,_,_,_,_,
	_,_,_,_,_,_,_,_,_,_,_,_,_,_,_,_,_,_,
	_,_,_,_,_,_,_,_,_,_,_,_,_,_,_,_,_,_,
	_,_,_,_,_,_,_,_,_,_,_,_,_,_,_,_,_,_,
	_,_,_,_,_,_,_,_,_,_,_,_,_,_,_,_,_,_,
	_,_,_,_,_,_,_,_,_,_,_,_,_,_,_,_,_,_,
	_,_,_,_,M,M,M,M,M,M,M,M,M,M,_,_,_,_,
	_,_,_,_,_,_,_,_,_,_,_,_,_,_,_,_,_,_,
	_,_,_,_,_,_,_,_,_,_,_,_,_,_,_,_,_,_,
--1 2 3 4 5 6 7 8 9 9 8 7 6 5 4 3 2 1


--2
	_,_,_,_,_,_,_,_,_,_,_,_,_,_,_,_,_,_,
	_,_,_,_,_,_,_,_,_,_,_,_,_,_,_,_,_,_,
	_,_,_,_,_,_,_,_,_,_,_,_,_,_,_,_,_,_,
	_,_,_,_,_,_,_,_,_,_,_,_,_,_,_,_,_,_,
	_,_,_,_,_,_,_,_,_,_,_,_,_,_,_,_,_,_,
	_,_,_,_,_,_,_,_,_,_,_,_,_,_,_,_,_,_,
	_,_,_,_,_,_,_,_,_,_,_,_,_,_,_,_,_,_,
	_,_,_,_,_,_,_,_,_,_,_,_,_,_,_,_,_,_,
	_,_,_,_,_,_,_,_,_,_,_,_,_,_,_,_,_,_,
	_,_,_,_,_,_,_,_,_,_,_,_,_,_,_,_,_,_,
	_,_,_,_,_,_,_,_,_,_,_,_,_,_,_,_,_,_,
	_,_,_,_,_,_,_,_,_,_,_,_,_,_,_,_,_,_,
	_,_,_,_,_,_,_,_,_,_,_,_,_,_,_,_,_,_,
	_,_,_,_,_,_,_,_,_,_,_,_,_,_,_,_,_,_,
	_,_,_,_,_,M,M,M,M,M,M,M,M,_,_,_,_,_,
	_,_,_,_,_,_,_,_,_,_,_,_,_,_,_,_,_,_,
	_,_,_,_,_,_,_,_,_,_,_,_,_,_,_,_,_,_,
--1 2 3 4 5 6 7 8 9 9 8 7 6 5 4 3 2 1

--1
	_,_,_,_,_,_,_,_,_,_,_,_,_,_,_,_,_,_,
	_,_,_,_,_,_,_,_,_,_,_,_,_,_,_,_,_,_,
	_,_,_,_,_,_,_,_,_,_,_,_,_,_,_,_,_,_,
	_,_,_,_,_,_,_,_,_,_,_,_,_,_,_,_,_,_,
	_,_,_,_,_,_,_,_,_,_,_,_,_,_,_,_,_,_,
	_,_,_,_,_,_,_,_,_,_,_,_,_,_,_,_,_,_,
	_,_,_,_,_,_,_,_,_,_,_,_,_,_,_,_,_,_,
	_,_,_,_,_,_,_,_,_,_,_,_,_,_,_,_,_,_,
	_,_,_,_,_,_,_,_,_,_,_,_,_,_,_,_,_,_,
	_,_,_,_,_,_,_,_,_,_,_,_,_,_,_,_,_,_,
	_,_,_,_,_,_,_,_,_,_,_,_,_,_,_,_,_,_,
	_,_,_,_,_,_,_,_,_,_,_,_,_,_,_,_,_,_,
	_,_,_,_,_,_,_,_,_,_,_,_,_,_,_,_,_,_,
	_,_,_,_,_,_,_,_,_,_,_,_,_,_,_,_,_,_,
	_,_,_,_,_,_,M,M,M,M,M,M,_,_,_,_,_,_,
	_,_,_,_,_,_,_,_,_,_,_,_,_,_,_,_,_,_,
	_,_,_,_,_,_,_,_,_,_,_,_,_,_,_,_,_,_,
--1 2 3 4 5 6 7 8 9 9 8 7 6 5 4 3 2 1


	}
}

