--pine tree schematic
local _ = {name = "air", prob = 0}
local l = {name = "default:pine_needles", prob = 255}
local t = {name = "default:pine_tree", prob = 255}

bd_basic_biomes.pinetree = {
	size = {x = 7, y = 11, z = 7},

	yslice_prob = {
		{ypos = 0, prob = 127}, -- trunk
		{ypos = 1, prob = 127},
		{ypos = 2, prob = 127},
		{ypos = 5, prob = 127}, -- leaves
		{ypos = 7, prob = 127},
	},

	data = {
	_,_,_,_,_,_,_,
	_,_,_,_,_,_,_,
	_,_,_,_,_,_,_,
	_,_,_,_,_,_,_,
	_,_,_,_,_,_,_,
	_,_,_,_,_,_,_,
	_,_,_,l,_,_,_,
	_,_,_,_,_,_,_,
	_,_,_,_,_,_,_,
	_,_,_,_,_,_,_,
	_,_,_,_,_,_,_,

	_,_,_,_,_,_,_,
	_,_,_,_,_,_,_,
	_,_,_,_,_,_,_,
	_,_,_,_,_,_,_,
	_,_,_,_,_,_,_,
	_,_,_,_,_,_,_,
	_,_,l,l,l,_,_,
	_,_,_,_,_,_,_,
	_,_,_,l,_,_,_,
	_,_,_,_,_,_,_,
	_,_,_,_,_,_,_,

	_,_,_,_,_,_,_,
	_,_,_,_,_,_,_,
	_,_,_,_,_,_,_,
	_,_,_,_,_,_,_,
	_,_,_,_,_,_,_,
	_,_,_,l,_,_,_,
	_,l,l,l,l,l,_,
	_,_,_,l,_,_,_,
	_,_,l,l,l,_,_,
	_,_,_,l,_,_,_,
	_,_,_,_,_,_,_,

	_,_,_,t,_,_,_,
	_,_,_,t,_,_,_,
	_,_,_,t,_,_,_,
	_,_,_,t,_,_,_,
	_,_,_,t,_,_,_,
	_,_,l,t,l,_,_,
	l,l,l,t,l,l,l,
	_,_,l,t,l,_,_,
	_,l,l,t,l,l,_,
	_,_,l,t,l,_,_,
	_,_,_,l,_,_,_,

	_,_,_,_,_,_,_,
	_,_,_,_,_,_,_,
	_,_,_,_,_,_,_,
	_,_,_,_,_,_,_,
	_,_,_,_,_,_,_,
	_,_,_,l,_,_,_,
	_,l,l,l,l,l,_,
	_,_,_,l,_,_,_,
	_,_,l,l,l,_,_,
	_,_,_,l,_,_,_,
	_,_,_,_,_,_,_,

	_,_,_,_,_,_,_,
	_,_,_,_,_,_,_,
	_,_,_,_,_,_,_,
	_,_,_,_,_,_,_,
	_,_,_,_,_,_,_,
	_,_,_,_,_,_,_,
	_,_,l,l,l,_,_,
	_,_,_,_,_,_,_,
	_,_,_,l,_,_,_,
	_,_,_,_,_,_,_,
	_,_,_,_,_,_,_,

	_,_,_,_,_,_,_,
	_,_,_,_,_,_,_,
	_,_,_,_,_,_,_,
	_,_,_,_,_,_,_,
	_,_,_,_,_,_,_,
	_,_,_,_,_,_,_,
	_,_,_,l,_,_,_,
	_,_,_,_,_,_,_,
	_,_,_,_,_,_,_,
	_,_,_,_,_,_,_,
	_,_,_,_,_,_,_,

	}
}
